Workbook

Sheet Pivot Table
A1: Row Labels | B1: Average of Total Engagement | C1: Sum of Shares | E1: Row Labels | F1: Sum of Ad_Spend
A2: Facebook | B2: 3677.6145 | C2: 39181 | E2: Facebook | F2: 1379539
A3: Instagram | B3: 3336.443 | C3: 41444 | E3: Instagram | F3: 1164373
A4: Twitter | B4: 3240.5696 | C4: 33728 | E4: Twitter | F4: 1060357
A5: YouTube | B5: 3609.1695 | C5: 28572 | E5: YouTube | F5: 1228647
A6: Grand Total | B6: 3459.2233 | C6: 142925 | E6: Grand Total | F6: 4832916
A8: Row Labels | B8: Sum of Clicks | E8: Row Labels | F8: Sum of Reach
A9: #AnytimeIsPepsiTime | B9: 170 | E9: Carousel | F9: 2084819
A10: #BetterWithPepsi | B10: 298 | E10: Image | F10: 2224104
A11: #LiveForNow | B11: 169 | E11: Reel | F11: 1630594
A12: #PepsiCoRefresh | B12: 128 | E12: Story | F12: 1455419
A13: #SmoothLikeNitroPepsi | B13: 245 | E13: Text | F13: 1456821
A14: #ThirstyForMore | B14: 155 | E14: Video | F14: 1379866
A15: Grand Total | B15: 1165 | E15: Grand Total | F15: 10231623
A17: Row Labels | B17: Sum of Clicks | E17: Row Labels | F17: Sum of Total Engaagement During Campaign | G17: Sum of Total_Budget
A18: #AnytimeIsPepsiTime | B18: 170 | E18: DailyWellness | F18: 33044 | G18: 180000
A19: #BetterWithPepsi | B19: 298 | E19: FestiveRadiance | F19: 106020 | G19: 200000
A20: #LiveForNow | B20: 169 | E20: NewYearRefresh | F20: 137691 | G20: 250000
A21: #PepsiCoRefresh | B21: 128 | E21: SummerSplash | F21: 103773 | G21: 150000
A22: #SmoothLikeNitroPepsi | B22: 245 | E22: Grand Total | F22: 380528 | G22: 780000
A23: #ThirstyForMore | B23: 155
A24: Grand Total | B24: 1165 | E24: Row Labels | F24: Sum of Total Engagement
E25: Before/After | F25: 1004723
A26: Row Labels | B26: Sum of Total Engagement | E26: During | F26: 33044
A27: Facebook | B27: 305242 | E27: Grand Total | F27: 1037767
A28: Instagram | B28: 263579
A29: Twitter | B29: 256005 | E29: Row Labels | F29: Sum of Total Engagement
A30: YouTube | B30: 212941 | E30: Before/After | F30: 900076
A31: Grand Total | B31: 1037767 | E31: During | F31: 137691
E32: Grand Total | F32: 1037767
A34: Row Labels | B34: Sum of Total Engagement | C34: Row Labels | D34: Sum of Average Engagement Rate
A35: DailyWellness | B35: 240483 | C35: DailyWellness | D35: 222770.15
A36: FestiveRadiance | B36: 201739 | C36: FestiveRadiance | D36: 186337.02
A37: NewYearRefresh | B37: 232821 | C37: NewYearRefresh | D37: 216256.27
A38: SummerSplash | B38: 173901 | C38: SummerSplash | D38: 161846.7
A39: Grand Total | B39: 848944 | C39: Grand Total | D39: 787210.15
A41: Row Labels | B41: Sum of Total Engagement
A42: Before/After | B42: 933994
A43: During | B43: 103773
A44: Grand Total | B44: 1037767
...

Sheet Posts
A1: Post ID | B1: Platform | C1: Date | D1: Content Type | E1: Post Text | F1: Likes | G1: Shares | H1: Comments | I1: Impressions | J1: Average Engagement Rate | K1: Total Engagement | L1: Reach | M1: Clicks | N1: Hashtags 1 | O1: Hashtags 2 | P1: Hashtags 3 | Q1: Unique Hashtags | R1: Count of Hashtags | S1: Campaign_Name | T1: During SummerSplash or Not | U1: During FestiveRadiance or Not | V1: During NewYearRefresh or Not | W1: During DailyWellness or Not
A2: P061 | B2: Twitter | C2: 2024-09-05 | D2: Video | E2: Check out our latest video on twitter! | F2: 4886 | G2: 983 | H2: 409 | I2: 43974 | J2: =F2+G2+H2/I2 -> 5869.0093 | K2: =F2+G2+H2 -> 6278 | L2: 43239 | M2: 65 | N2: #PepsiCoRefresh | Q2: {=_xlfn.UNIQUE(Posts!N2:N301)} -> #VALUE! | R2: =COUNTIF(N:P,"#PepsiCoRefresh") -> 107 | S2: SummerSplash | T2: =IF(AND(C2>='Campaign Metadata'!B$2,Posts!C2<='Campaign Metadata'!C$2),"During","Before/After") -> Before/After | U2: =IF(AND(C2>='Campaign Metadata'!B$3,Posts!C2<='Campaign Metadata'!C$3),"During","Before/After") -> Before/After | V2: =IF(AND(C2>='Campaign Metadata'!B$4,Posts!C2<='Campaign Metadata'!C$4),"During","Before/After") -> Before/After | W2: =IF(AND(C2>='Campaign Metadata'!B$5,Posts!C2<='Campaign Metadata'!C$5),"During","Before/After") -> Before/After
A3: P144 | B3: YouTube | C3: 2024-10-28 | D3: Story | E3: Check out our latest story on youtube! | F3: 4929 | G3: 749 | H3: 452 | I3: 93651 | J3: =F3+G3+H3/I3 -> 5678.0048 | K3: =F3+G3+H3 -> 6130 | L3: 92810 | M3: 66 | N3: #ThirstyForMore | R3: =COUNTIF(N:P,"#ThirstyForMore") -> 102 | S3: DailyWellness | T3: =IF(AND(C3>='Campaign Metadata'!B$2,Posts!C3<='Campaign Metadata'!C$2),"During","Before/After") -> Before/After | U3: =IF(AND(C3>='Campaign Metadata'!B$3,Posts!C3<='Campaign Metadata'!C$3),"During","Before/After") -> Before/After | V3: =IF(AND(C3>='Campaign Metadata'!B$4,Posts!C3<='Campaign Metadata'!C$4),"During","Before/After") -> During | W3: =IF(AND(C3>='Campaign Metadata'!B$5,Posts!C3<='Campaign Metadata'!C$5),"During","Before/After") -> Before/After
A4: P164 | B4: YouTube | C4: 2025-02-27 | D4: Text | E4: Check out our latest text on youtube! | F4: 4934 | G4: 971 | H4: 156 | I4: 39472 | J4: =F4+G4+H4/I4 -> 5905.004 | K4: =F4+G4+H4 -> 6061 | L4: 39025 | M4: 169 | N4: #PepsiCoRefresh | O4: #AnytimeIsPepsiTime | R4: =COUNTIF(N:P,"#LiveForNow") -> 103 | S4: DailyWellness | T4: =IF(AND(C4>='Campaign Metadata'!B$2,Posts!C4<='Campaign Metadata'!C$2),"During","Before/After") -> Before/After | U4: =IF(AND(C4>='Campaign Metadata'!B$3,Posts!C4<='Campaign Metadata'!C$3),"During","Before/After") -> Before/After | V4: =IF(AND(C4>='Campaign Metadata'!B$4,Posts!C4<='Campaign Metadata'!C$4),"During","Before/After") -> Before/After | W4: =IF(AND(C4>='Campaign Metadata'!B$5,Posts!C4<='Campaign Metadata'!C$5),"During","Before/After") -> Before/After
A5: P261 | B5: Instagram | C5: 2024-10-27 | D5: Image | E5: Check out our latest image on instagram! | F5: 4853 | G5: 837 | H5: 340 | I5: 72795 | J5: =F5+G5+H5/I5 -> 5690.0047 | K5: =F5+G5+H5 -> 6030 | L5: 72237 | M5: 170 | N5: #ThirstyForMore | Q5: #AnytimeIsPepsiTime | R5: =COUNTIF(N:P,"#AnytimeIsPepsiTime") -> 15 | S5: SummerSplash | T5: =IF(AND(C5>='Campaign Metadata'!B$2,Posts!C5<='Campaign Metadata'!C$2),"During","Before/After") -> Before/After | U5: =IF(AND(C5>='Campaign Metadata'!B$3,Posts!C5<='Campaign Metadata'!C$3),"During","Before/After") -> Before/After | V5: =IF(AND(C5>='Campaign Metadata'!B$4,Posts!C5<='Campaign Metadata'!C$4),"During","Before/After") -> During | W5: =IF(AND(C5>='Campaign Metadata'!B$5,Posts!C5<='Campaign Metadata'!C$5),"During","Before/After") -> Before/After
A6: P244 | B6: YouTube | C6: 2024-10-25 | D6: Video | E6: Check out our latest video on youtube! | F6: 4661 | G6: 935 | H6: 433 | I6: 23305 | J6: =F6+G6+H6/I6 -> 5596.0186 | K6: =F6+G6+H6 -> 6029 | L6: 22583 | M6: 63 | N6: #LiveForNow | Q6: #PepsiCoRefresh | R6: =COUNTIF(N:P,"#PepsiCoRefresh") -> 107 | S6: NewYearRefresh | T6: =IF(AND(C6>='Campaign Metadata'!B$2,Posts!C6<='Campaign Metadata'!C$2),"During","Before/After") -> Before/After | U6: =IF(AND(C6>='Campaign Metadata'!B$3,Posts!C6<='Campaign Metadata'!C$3),"During","Before/After") -> Before/After | V6: =IF(AND(C6>='Campaign Metadata'!B$4,Posts!C6<='Campaign Metadata'!C$4),"During","Before/After") -> During | W6: =IF(AND(C6>='Campaign Metadata'!B$5,Posts!C6<='Campaign Metadata'!C$5),"During","Before/After") -> Before/After
A7: P215 | B7: Facebook | C7: 2025-05-06 | D7: Image | E7: Check out our latest image on facebook! | F7: 4872 | G7: 925 | H7: 176 | I7: 82824 | J7: =F7+G7+H7/I7 -> 5797.0021 | K7: =F7+G7+H7 -> 5973 | L7: 82543 | M7: 89 | N7: #ThirstyForMore | Q7: #ThirstyForMore | R7: =COUNTIF(N:P,"#ThirstyForMore") -> 102 | S7: FestiveRadiance | T7: =IF(AND(C7>='Campaign Metadata'!B$2,Posts!C7<='Campaign Metadata'!C$2),"During","Before/After") -> Before/After | U7: =IF(AND(C7>='Campaign Metadata'!B$3,Posts!C7<='Campaign Metadata'!C$3),"During","Before/After") -> Before/After | V7: =IF(AND(C7>='Campaign Metadata'!B$4,Posts!C7<='Campaign Metadata'!C$4),"During","Before/After") -> Before/After | W7: =IF(AND(C7>='Campaign Metadata'!B$5,Posts!C7<='Campaign Metadata'!C$5),"During","Before/After") -> Before/After
A8: P106 | B8: Instagram | C8: 2025-02-04 | D8: Image | E8: Check out our latest image on instagram! | F8: 4619 | G8: 821 | H8: 499 | I8: 69285 | J8: =F8+G8+H8/I8 -> 5440.0072 | K8: =F8+G8+H8 -> 5939 | L8: 69141 | M8: 298 | N8: #PepsiCoRefresh | Q8: #BetterWithPepsi | R8: =COUNTIF(N:P,"#BetterWithPepsi") -> 7 | S8: DailyWellness | T8: =IF(AND(C8>='Campaign Metadata'!B$2,Posts!C8<='Campaign Metadata'!C$2),"During","Before/After") -> Before/After | U8: =IF(AND(C8>='Campaign Metadata'!B$3,Posts!C8<='Campaign Metadata'!C$3),"During","Before/After") -> Before/After | V8: =IF(AND(C8>='Campaign Metadata'!B$4,Posts!C8<='Campaign Metadata'!C$4),"During","Before/After") -> Before/After | W8: =IF(AND(C8>='Campaign Metadata'!B$5,Posts!C8<='Campaign Metadata'!C$5),"During","Before/After") -> Before/After
A9: P161 | B9: Twitter | C9: 2025-02-19 | D9: Text | E9: Check out our latest text on twitter! | F9: 4671 | G9: 876 | H9: 366 | I9: 51381 | J9: =F9+G9+H9/I9 -> 5547.0071 | K9: =F9+G9+H9 -> 5913 | L9: 50565 | M9: 245 | N9: #PepsiCoRefresh | Q9: #SmoothLikeNitroPepsi | R9: =COUNTIF(N:P,"#SmoothLikeNitroPepsi") -> 5 | S9: DailyWellness | T9: =IF(AND(C9>='Campaign Metadata'!B$2,Posts!C9<='Campaign Metadata'!C$2),"During","Before/After") -> Before/After | U9: =IF(AND(C9>='Campaign Metadata'!B$3,Posts!C9<='Campaign Metadata'!C$3),"During","Before/After") -> Before/After | V9: =IF(AND(C9>='Campaign Metadata'!B$4,Posts!C9<='Campaign Metadata'!C$4),"During","Before/After") -> Before/After | W9: =IF(AND(C9>='Campaign Metadata'!B$5,Posts!C9<='Campaign Metadata'!C$5),"During","Before/After") -> Before/After
A10: P228 | B10: Instagram | C10: 2024-07-01 | D10: Story | E10: Check out our latest story on instagram! | F10: 4808 | G10: 772 | H10: 320 | I10: 72120 | J10: =F10+G10+H10/I10 -> 5580.0044 | K10: =F10+G10+H10 -> 5900 | L10: 71696 | M10: 195 | N10: #ThirstyForMore | S10: SummerSplash | T10: =IF(AND(C10>='Campaign Metadata'!B$2,Posts!C10<='Campaign Metadata'!C$2),"During","Before/After") -> During | U10: =IF(AND(C10>='Campaign Metadata'!B$3,Posts!C10<='Campaign Metadata'!C$3),"During","Before/After") -> Before/After | V10: =IF(AND(C10>='Campaign Metadata'!B$4,Posts!C10<='Campaign Metadata'!C$4),"During","Before/After") -> Before/After | W10: =IF(AND(C10>='Campaign Metadata'!B$5,Posts!C10<='Campaign Metadata'!C$5),"During","Before/After") -> Before/After
A11: P279 | B11: YouTube | C11: 2024-09-02 | D11: Image | E11: Check out our latest image on youtube! | F11: 4905 | G11: 845 | H11: 129 | I11: 98100 | J11: =F11+G11+H11/I11 -> 5750.0013 | K11: =F11+G11+H11 -> 5879 | L11: 97772 | M11: 279 | N11: #PepsiCoRefresh | S11: FestiveRadiance | T11: =IF(AND(C11>='Campaign Metadata'!B$2,Posts!C11<='Campaign Metadata'!C$2),"During","Before/After") -> Before/After | U11: =IF(AND(C11>='Campaign Metadata'!B$3,Posts!C11<='Campaign Metadata'!C$3),"During","Before/After") -> Before/After | V11: =IF(AND(C11>='Campaign Metadata'!B$4,Posts!C11<='Campaign Metadata'!C$4),"During","Before/After") -> Before/After | W11: =IF(AND(C11>='Campaign Metadata'!B$5,Posts!C11<='Campaign Metadata'!C$5),"During","Before/After") -> Before/After
A12: P288 | B12: YouTube | C12: 2025-04-17 | D12: Carousel | E12: Check out our latest carousel on youtube! | F12: 4780 | G12: 691 | H12: 380 | I12: 86040 | J12: =F12+G12+H12/I12 -> 5471.0044 | K12: =F12+G12+H12 -> 5851 | L12: 85743 | M12: 262 | N12: #LiveForNow | S12: NewYearRefresh | T12: =IF(AND(C12>='Campaign Metadata'!B$2,Posts!C12<='Campaign Metadata'!C$2),"During","Before/After") -> Before/After | U12: =IF(AND(C12>='Campaign Metadata'!B$3,Posts!C12<='Campaign Metadata'!C$3),"During","Before/After") -> Before/After | V12: =IF(AND(C12>='Campaign Metadata'!B$4,Posts!C12<='Campaign Metadata'!C$4),"During","Before/After") -> Before/After | W12: =IF(AND(C12>='Campaign Metadata'!B$5,Posts!C12<='Campaign Metadata'!C$5),"During","Before/After") -> Before/After
A13: P229 | B13: Instagram | C13: 2024-07-03 | D13: Carousel | E13: Check out our latest carousel on instagram! | F13: 4799 | G13: 694 | H13: 289 | I13: 43191 | J13: =F13+G13+H13/I13 -> 5493.0067 | K13: =F13+G13+H13 -> 5782 | L13: 42228 | M13: 118 | N13: #PepsiCoRefresh | T13: =IF(AND(C13>='Campaign Metadata'!B$2,Posts!C13<='Campaign Metadata'!C$2),"During","Before/After") -> During | U13: =IF(AND(C13>='Campaign Metadata'!B$3,Posts!C13<='Campaign Metadata'!C$3),"During","Before/After") -> Before/After | V13: =IF(AND(C13>='Campaign Metadata'!B$4,Posts!C13<='Campaign Metadata'!C$4),"During","Before/After") -> Before/After | W13: =IF(AND(C13>='Campaign Metadata'!B$5,Posts!C13<='Campaign Metadata'!C$5),"During","Before/After") -> Before/After
A14: P217 | B14: Facebook | C14: 2024-12-03 | D14: Image | E14: Check out our latest image on facebook! | F14: 4606 | G14: 931 | H14: 230 | I14: 92120 | J14: =F14+G14+H14/I14 -> 5537.0025 | K14: =F14+G14+H14 -> 5767 | L14: 91440 | M14: 56 | N14: #PepsiCoRefresh | T14: =IF(AND(C14>='Campaign Metadata'!B$2,Posts!C14<='Campaign Metadata'!C$2),"During","Before/After") -> Before/After | U14: =IF(AND(C14>='Campaign Metadata'!B$3,Posts!C14<='Campaign Metadata'!C$3),"During","Before/After") -> Before/After | V14: =IF(AND(C14>='Campaign Metadata'!B$4,Posts!C14<='Campaign Metadata'!C$4),"During","Before/After") -> Before/After | W14: =IF(AND(C14>='Campaign Metadata'!B$5,Posts!C14<='Campaign Metadata'!C$5),"During","Before/After") -> Before/After
A15: P107 | B15: YouTube | C15: 2024-06-21 | D15: Image | E15: Check out our latest image on youtube! | F15: 4832 | G15: 893 | H15: 10 | I15: 91808 | J15: =F15+G15+H15/I15 -> 5725.0001 | K15: =F15+G15+H15 -> 5735 | L15: 91296 | M15: 182 | N15: #PepsiCoRefresh | T15: =IF(AND(C15>='Campaign Metadata'!B$2,Posts!C15<='Campaign Metadata'!C$2),"During","Before/After") -> During | U15: =IF(AND(C15>='Campaign Metadata'!B$3,Posts!C15<='Campaign Metadata'!C$3),"During","Before/After") -> Before/After | V15: =IF(AND(C15>='Campaign Metadata'!B$4,Posts!C15<='Campaign Metadata'!C$4),"During","Before/After") -> Before/After | W15: =IF(AND(C15>='Campaign Metadata'!B$5,Posts!C15<='Campaign Metadata'!C$5),"During","Before/After") -> Before/After
A16: P131 | B16: Instagram | C16: 2024-10-21 | D16: Reel | E16: Check out our latest reel on instagram! | F16: 4840 | G16: 658 | H16: 211 | I16: 43560 | J16: =F16+G16+H16/I16 -> 5498.0048 | K16: =F16+G16+H16 -> 5709 | L16: 43225 | M16: 57 | N16: #LiveForNow | S16: NewYearRefresh | T16: =IF(AND(C16>='Campaign Metadata'!B$2,Posts!C16<='Campaign Metadata'!C$2),"During","Before/After") -> Before/After | U16: =IF(AND(C16>='Campaign Metadata'!B$3,Posts!C16<='Campaign Metadata'!C$3),"During","Before/After") -> Before/After | V16: =IF(AND(C16>='Campaign Metadata'!B$4,Posts!C16<='Campaign Metadata'!C$4),"During","Before/After") -> During | W16: =IF(AND(C16>='Campaign Metadata'!B$5,Posts!C16<='Campaign Metadata'!C$5),"During","Before/After") -> Before/After
A17: P167 | B17: Instagram | C17: 2024-11-28 | D17: Text | E17: Check out our latest text on instagram! | F17: 4771 | G17: 818 | H17: 56 | I17: 57252 | J17: =F17+G17+H17/I17 -> 5589.001 | K17: =F17+G17+H17 -> 5645 | L17: 56378 | M17: 150 | N17: #LiveForNow | T17: =IF(AND(C17>='Campaign Metadata'!B$2,Posts!C17<='Campaign Metadata'!C$2),"During","Before/After") -> Before/After | U17: =IF(AND(C17>='Campaign Metadata'!B$3,Posts!C17<='Campaign Metadata'!C$3),"During","Before/After") -> Before/After | V17: =IF(AND(C17>='Campaign Metadata'!B$4,Posts!C17<='Campaign Metadata'!C$4),"During","Before/After") -> Before/After | W17: =IF(AND(C17>='Campaign Metadata'!B$5,Posts!C17<='Campaign Metadata'!C$5),"During","Before/After") -> Before/After
A18: P152 | B18: Facebook | C18: 2025-04-22 | D18: Image | E18: Check out our latest image on facebook! | F18: 4804 | G18: 550 | H18: 270 | I18: 28824 | J18: =F18+G18+H18/I18 -> 5354.0094 | K18: =F18+G18+H18 -> 5624 | L18: 28370 | M18: 47 | N18: #ThirstyForMore | S18: DailyWellness | T18: =IF(AND(C18>='Campaign Metadata'!B$2,Posts!C18<='Campaign Metadata'!C$2),"During","Before/After") -> Before/After | U18: =IF(AND(C18>='Campaign Metadata'!B$3,Posts!C18<='Campaign Metadata'!C$3),"During","Before/After") -> Before/After | V18: =IF(AND(C18>='Campaign Metadata'!B$4,Posts!C18<='Campaign Metadata'!C$4),"During","Before/After") -> Before/After | W18: =IF(AND(C18>='Campaign Metadata'!B$5,Posts!C18<='Campaign Metadata'!C$5),"During","Before/After") -> Before/After
A19: P272 | B19: Instagram | C19: 2025-03-27 | D19: Text | E19: Check out our latest text on instagram! | F19: 4941 | G19: 414 | H19: 266 | I19: 39528 | J19: =F19+G19+H19/I19 -> 5355.0067 | K19: =F19+G19+H19 -> 5621 | L19: 39154 | M19: 217 | N19: #PepsiCoRefresh | S19: NewYearRefresh | T19: =IF(AND(C19>='Campaign Metadata'!B$2,Posts!C19<='Campaign Metadata'!C$2),"During","Before/After") -> Before/After | U19: =IF(AND(C19>='Campaign Metadata'!B$3,Posts!C19<='Campaign Metadata'!C$3),"During","Before/After") -> During | V19: =IF(AND(C19>='Campaign Metadata'!B$4,Posts!C19<='Campaign Metadata'!C$4),"During","Before/After") -> Before/After | W19: =IF(AND(C19>='Campaign Metadata'!B$5,Posts!C19<='Campaign Metadata'!C$5),"During","Before/After") -> Before/After
A20: P021 | B20: Instagram | C20: 2025-01-04 | D20: Reel | E20: Check out our latest reel on instagram! | F20: 4838 | G20: 640 | H20: 128 | I20: 72570 | J20: =F20+G20+H20/I20 -> 5478.0018 | K20: =F20+G20+H20 -> 5606 | L20: 72396 | M20: 83 | N20: #LiveForNow | S20: DailyWellness | T20: =IF(AND(C20>='Campaign Metadata'!B$2,Posts!C20<='Campaign Metadata'!C$2),"During","Before/After") -> Before/After | U20: =IF(AND(C20>='Campaign Metadata'!B$3,Posts!C20<='Campaign Metadata'!C$3),"During","Before/After") -> Before/After | V20: =IF(AND(C20>='Campaign Metadata'!B$4,Posts!C20<='Campaign Metadata'!C$4),"During","Before/After") -> Before/After | W20: =IF(AND(C20>='Campaign Metadata'!B$5,Posts!C20<='Campaign Metadata'!C$5),"During","Before/After") -> During
A21: P197 | B21: Twitter | C21: 2024-10-22 | D21: Reel | E21: Check out our latest reel on twitter! | F21: 4782 | G21: 721 | H21: 82 | I21: 86076 | J21: =F21+G21+H21/I21 -> 5503.001 | K21: =F21+G21+H21 -> 5585 | L21: 85339 | M21: 19 | N21: #ThirstyForMore | S21: SummerSplash | T21: =IF(AND(C21>='Campaign Metadata'!B$2,Posts!C21<='Campaign Metadata'!C$2),"During","Before/After") -> Before/After | U21: =IF(AND(C21>='Campaign Metadata'!B$3,Posts!C21<='Campaign Metadata'!C$3),"During","Before/After") -> Before/After | V21: =IF(AND(C21>='Campaign Metadata'!B$4,Posts!C21<='Campaign Metadata'!C$4),"During","Before/After") -> During | W21: =IF(AND(C21>='Campaign Metadata'!B$5,Posts!C21<='Campaign Metadata'!C$5),"During","Before/After") -> Before/After
A22: P101 | B22: YouTube | C22: 2024-10-18 | D22: Video | E22: Check out our latest video on youtube! | F22: 4450 | G22: 983 | H22: 143 | I22: 75650 | J22: =F22+G22+H22/I22 -> 5433.0019 | K22: =F22+G22+H22 -> 5576 | L22: 75008 | M22: 12 | N22: #LiveForNow | S22: NewYearRefresh | T22: =IF(AND(C22>='Campaign Metadata'!B$2,Posts!C22<='Campaign Metadata'!C$2),"During","Before/After") -> Before/After | U22: =IF(AND(C22>='Campaign Metadata'!B$3,Posts!C22<='Campaign Metadata'!C$3),"During","Before/After") -> Before/After | V22: =IF(AND(C22>='Campaign Metadata'!B$4,Posts!C22<='Campaign Metadata'!C$4),"During","Before/After") -> During | W22: =IF(AND(C22>='Campaign Metadata'!B$5,Posts!C22<='Campaign Metadata'!C$5),"During","Before/After") -> Before/After
A23: P191 | B23: YouTube | C23: 2024-12-03 | D23: Story | E23: Check out our latest story on youtube! | F23: 4285 | G23: 886 | H23: 376 | I23: 55705 | J23: =F23+G23+H23/I23 -> 5171.0067 | K23: =F23+G23+H23 -> 5547 | L23: 55556 | M23: 51 | N23: #LiveForNow | S23: NewYearRefresh | T23: =IF(AND(C23>='Campaign Metadata'!B$2,Posts!C23<='Campaign Metadata'!C$2),"During","Before/After") -> Before/After | U23: =IF(AND(C23>='Campaign Metadata'!B$3,Posts!C23<='Campaign Metadata'!C$3),"During","Before/After") -> Before/After | V23: =IF(AND(C23>='Campaign Metadata'!B$4,Posts!C23<='Campaign Metadata'!C$4),"During","Before/After") -> Before/After | W23: =IF(AND(C23>='Campaign Metadata'!B$5,Posts!C23<='Campaign Metadata'!C$5),"During","Before/After") -> Before/After
A24: P278 | B24: Twitter | C24: 2024-11-26 | D24: Text | E24: Check out our latest text on twitter! | F24: 4516 | G24: 836 | H24: 169 | I24: 49676 | J24: =F24+G24+H24/I24 -> 5352.0034 | K24: =F24+G24+H24 -> 5521 | L24: 49257 | M24: 282 | N24: #ThirstyForMore | S24: DailyWellness | T24: =IF(AND(C24>='Campaign Metadata'!B$2,Posts!C24<='Campaign Metadata'!C$2),"During","Before/After") -> Before/After | U24: =IF(AND(C24>='Campaign Metadata'!B$3,Posts!C24<='Campaign Metadata'!C$3),"During","Before/After") -> Before/After | V24: =IF(AND(C24>='Campaign Metadata'!B$4,Posts!C24<='Campaign Metadata'!C$4),"During","Before/After") -> Before/After | W24: =IF(AND(C24>='Campaign Metadata'!B$5,Posts!C24<='Campaign Metadata'!C$5),"During","Before/After") -> Before/After
A25: P238 | B25: Twitter | C25: 2024-07-16 | D25: Text | E25: Check out our latest text on twitter! | F25: 4725 | G25: 400 | H25: 362 | I25: 75600 | J25: =F25+G25+H25/I25 -> 5125.0048 | K25: =F25+G25+H25 -> 5487 | L25: 74927 | M25: 43 | N25: #LiveForNow | S25: DailyWellness | T25: =IF(AND(C25>='Campaign Metadata'!B$2,Posts!C25<='Campaign Metadata'!C$2),"During","Before/After") -> Before/After | U25: =IF(AND(C25>='Campaign Metadata'!B$3,Posts!C25<='Campaign Metadata'!C$3),"During","Before/After") -> Before/After | V25: =IF(AND(C25>='Campaign Metadata'!B$4,Posts!C25<='Campaign Metadata'!C$4),"During","Before/After") -> Before/After | W25: =IF(AND(C25>='Campaign Metadata'!B$5,Posts!C25<='Campaign Metadata'!C$5),"During","Before/After") -> Before/After
A26: P150 | B26: YouTube | C26: 2024-08-22 | D26: Carousel | E26: Check out our latest carousel on youtube! | F26: 4295 | G26: 853 | H26: 325 | I26: 85900 | J26: =F26+G26+H26/I26 -> 5148.0038 | K26: =F26+G26+H26 -> 5473 | L26: 85788 | M26: 290 | N26: #PepsiCoRefresh | S26: DailyWellness | T26: =IF(AND(C26>='Campaign Metadata'!B$2,Posts!C26<='Campaign Metadata'!C$2),"During","Before/After") -> Before/After | U26: =IF(AND(C26>='Campaign Metadata'!B$3,Posts!C26<='Campaign Metadata'!C$3),"During","Before/After") -> Before/After | V26: =IF(AND(C26>='Campaign Metadata'!B$4,Posts!C26<='Campaign Metadata'!C$4),"During","Before/After") -> Before/After | W26: =IF(AND(C26>='Campaign Metadata'!B$5,Posts!C26<='Campaign Metadata'!C$5),"During","Before/After") -> Before/After
A27: P118 | B27: Facebook | C27: 2024-11-04 | D27: Image | E27: Check out our latest image on facebook! | F27: 4551 | G27: 714 | H27: 207 | I27: 68265 | J27: =F27+G27+H27/I27 -> 5265.003 | K27: =F27+G27+H27 -> 5472 | L27: 67754 | M27: 57 | N27: #LiveForNow | S27: NewYearRefresh | T27: =IF(AND(C27>='Campaign Metadata'!B$2,Posts!C27<='Campaign Metadata'!C$2),"During","Before/After") -> Before/After | U27: =IF(AND(C27>='Campaign Metadata'!B$3,Posts!C27<='Campaign Metadata'!C$3),"During","Before/After") -> Before/After | V27: =IF(AND(C27>='Campaign Metadata'!B$4,Posts!C27<='Campaign Metadata'!C$4),"During","Before/After") -> Before/After | W27: =IF(AND(C27>='Campaign Metadata'!B$5,Posts!C27<='Campaign Metadata'!C$5),"During","Before/After") -> Before/After
A28: P067 | B28: Facebook | C28: 2025-03-29 | D28: Carousel | E28: Check out our latest carousel on facebook! | F28: 4712 | G28: 568 | H28: 127 | I28: 84816 | J28: =F28+G28+H28/I28 -> 5280.0015 | K28: =F28+G28+H28 -> 5407 | L28: 84691 | M28: 100 | N28: #ThirstyForMore | S28: NewYearRefresh | T28: =IF(AND(C28>='Campaign Metadata'!B$2,Posts!C28<='Campaign Metadata'!C$2),"During","Before/After") -> Before/After | U28: =IF(AND(C28>='Campaign Metadata'!B$3,Posts!C28<='Campaign Metadata'!C$3),"During","Before/After") -> During | V28: =IF(AND(C28>='Campaign Metadata'!B$4,Posts!C28<='Campaign Metadata'!C$4),"During","Before/After") -> Before/After | W28: =IF(AND(C28>='Campaign Metadata'!B$5,Posts!C28<='Campaign Metadata'!C$5),"During","Before/After") -> Before/After
A29: P097 | B29: Instagram | C29: 2024-08-13 | D29: Image | E29: Check out our latest image on instagram! | F29: 4739 | G29: 527 | H29: 135 | I29: 61607 | J29: =F29+G29+H29/I29 -> 5266.0022 | K29: =F29+G29+H29 -> 5401 | L29: 61333 | M29: 36 | N29: #PepsiCoRefresh | O29: #AnytimeIsPepsiTime | S29: FestiveRadiance | T29: =IF(AND(C29>='Campaign Metadata'!B$2,Posts!C29<='Campaign Metadata'!C$2),"During","Before/After") -> Before/After | U29: =IF(AND(C29>='Campaign Metadata'!B$3,Posts!C29<='Campaign Metadata'!C$3),"During","Before/After") -> Before/After | V29: =IF(AND(C29>='Campaign Metadata'!B$4,Posts!C29<='Campaign Metadata'!C$4),"During","Before/After") -> Before/After | W29: =IF(AND(C29>='Campaign Metadata'!B$5,Posts!C29<='Campaign Metadata'!C$5),"During","Before/After") -> Before/After
A30: P241 | B30: Facebook | C30: 2025-01-18 | D30: Story | E30: Check out our latest story on facebook! | F30: 4321 | G30: 874 | H30: 172 | I30: 30247 | J30: =F30+G30+H30/I30 -> 5195.0057 | K30: =F30+G30+H30 -> 5367 | L30: 29254 | M30: 122 | N30: #PepsiCoRefresh | S30: DailyWellness | T30: =IF(AND(C30>='Campaign Metadata'!B$2,Posts!C30<='Campaign Metadata'!C$2),"During","Before/After") -> Before/After | U30: =IF(AND(C30>='Campaign Metadata'!B$3,Posts!C30<='Campaign Metadata'!C$3),"During","Before/After") -> Before/After | V30: =IF(AND(C30>='Campaign Metadata'!B$4,Posts!C30<='Campaign Metadata'!C$4),"During","Before/After") -> Before/After | W30: =IF(AND(C30>='Campaign Metadata'!B$5,Posts!C30<='Campaign Metadata'!C$5),"During","Before/After") -> Before/After
A31: P280 | B31: YouTube | C31: 2024-10-21 | D31: Video | E31: Check out our latest video on youtube! | F31: 4275 | G31: 680 | H31: 385 | I31: 64125 | J31: =F31+G31+H31/I31 -> 4955.006 | K31: =F31+G31+H31 -> 5340 | L31: 63650 | M31: 104 | N31: #ThirstyForMore | O31: #PepsiCoRefresh | P31: #AnytimeIsPepsiTime | S31: DailyWellness | T31: =IF(AND(C31>='Campaign Metadata'!B$2,Posts!C31<='Campaign Metadata'!C$2),"During","Before/After") -> Before/After | U31: =IF(AND(C31>='Campaign Metadata'!B$3,Posts!C31<='Campaign Metadata'!C$3),"During","Before/After") -> Before/After | V31: =IF(AND(C31>='Campaign Metadata'!B$4,Posts!C31<='Campaign Metadata'!C$4),"During","Before/After") -> During | W31: =IF(AND(C31>='Campaign Metadata'!B$5,Posts!C31<='Campaign Metadata'!C$5),"During","Before/After") -> Before/After
A32: P260 | B32: Instagram | C32: 2025-02-12 | D32: Story | E32: Check out our latest story on instagram! | F32: 4332 | G32: 771 | H32: 219 | I32: 60648 | J32: =F32+G32+H32/I32 -> 5103.0036 | K32: =F32+G32+H32 -> 5322 | L32: 60397 | M32: 10 | N32: #PepsiCoRefresh | O32: #ThirstyForMore | P32: #BetterWithPepsi | S32: NewYearRefresh | T32: =IF(AND(C32>='Campaign Metadata'!B$2,Posts!C32<='Campaign Metadata'!C$2),"During","Before/After") -> Before/After | U32: =IF(AND(C32>='Campaign Metadata'!B$3,Posts!C32<='Campaign Metadata'!C$3),"During","Before/After") -> Before/After | V32: =IF(AND(C32>='Campaign Metadata'!B$4,Posts!C32<='Campaign Metadata'!C$4),"During","Before/After") -> Before/After | W32: =IF(AND(C32>='Campaign Metadata'!B$5,Posts!C32<='Campaign Metadata'!C$5),"During","Before/After") -> Before/After
A33: P040 | B33: Twitter | C33: 2025-03-07 | D33: Image | E33: Check out our latest image on twitter! | F33: 4750 | G33: 151 | H33: 415 | I33: 38000 | J33: =F33+G33+H33/I33 -> 4901.0109 | K33: =F33+G33+H33 -> 5316 | L33: 37792 | M33: 299 | N33: #ThirstyForMore | S33: DailyWellness | T33: =IF(AND(C33>='Campaign Metadata'!B$2,Posts!C33<='Campaign Metadata'!C$2),"During","Before/After") -> Before/After | U33: =IF(AND(C33>='Campaign Metadata'!B$3,Posts!C33<='Campaign Metadata'!C$3),"During","Before/After") -> During | V33: =IF(AND(C33>='Campaign Metadata'!B$4,Posts!C33<='Campaign Metadata'!C$4),"During","Before/After") -> Before/After | W33: =IF(AND(C33>='Campaign Metadata'!B$5,Posts!C33<='Campaign Metadata'!C$5),"During","Before/After") -> Before/After
A34: P193 | B34: Twitter | C34: 2024-09-11 | D34: Image | E34: Check out our latest image on twitter! | F34: 4858 | G34: 317 | H34: 129 | I34: 53438 | J34: =F34+G34+H34/I34 -> 5175.0024 | K34: =F34+G34+H34 -> 5304 | L34: 52687 | M34: 223 | N34: #ThirstyForMore | S34: NewYearRefresh | T34: =IF(AND(C34>='Campaign Metadata'!B$2,Posts!C34<='Campaign Metadata'!C$2),"During","Before/After") -> Before/After | U34: =IF(AND(C34>='Campaign Metadata'!B$3,Posts!C34<='Campaign Metadata'!C$3),"During","Before/After") -> Before/After | V34: =IF(AND(C34>='Campaign Metadata'!B$4,Posts!C34<='Campaign Metadata'!C$4),"During","Before/After") -> Before/After | W34: =IF(AND(C34>='Campaign Metadata'!B$5,Posts!C34<='Campaign Metadata'!C$5),"During","Before/After") -> Before/After
A35: P242 | B35: Facebook | C35: 2024-07-07 | D35: Reel | E35: Check out our latest reel on facebook! | F35: 4767 | G35: 190 | H35: 340 | I35: 28602 | J35: =F35+G35+H35/I35 -> 4957.0119 | K35: =F35+G35+H35 -> 5297 | L35: 28044 | M35: 210 | N35: #ThirstyForMore | S35: NewYearRefresh | T35: =IF(AND(C35>='Campaign Metadata'!B$2,Posts!C35<='Campaign Metadata'!C$2),"During","Before/After") -> During | U35: =IF(AND(C35>='Campaign Metadata'!B$3,Posts!C35<='Campaign Metadata'!C$3),"During","Before/After") -> Before/After | V35: =IF(AND(C35>='Campaign Metadata'!B$4,Posts!C35<='Campaign Metadata'!C$4),"During","Before/After") -> Before/After | W35: =IF(AND(C35>='Campaign Metadata'!B$5,Posts!C35<='Campaign Metadata'!C$5),"During","Before/After") -> Before/After
A36: P108 | B36: Twitter | C36: 2025-03-25 | D36: Video | E36: Check out our latest video on twitter! | F36: 4050 | G36: 871 | H36: 347 | I36: 52650 | J36: =F36+G36+H36/I36 -> 4921.0066 | K36: =F36+G36+H36 -> 5268 | L36: 51755 | M36: 209 | N36: #PepsiCoRefresh | S36: FestiveRadiance | T36: =IF(AND(C36>='Campaign Metadata'!B$2,Posts!C36<='Campaign Metadata'!C$2),"During","Before/After") -> Before/After | U36: =IF(AND(C36>='Campaign Metadata'!B$3,Posts!C36<='Campaign Metadata'!C$3),"During","Before/After") -> During | V36: =IF(AND(C36>='Campaign Metadata'!B$4,Posts!C36<='Campaign Metadata'!C$4),"During","Before/After") -> Before/After | W36: =IF(AND(C36>='Campaign Metadata'!B$5,Posts!C36<='Campaign Metadata'!C$5),"During","Before/After") -> Before/After
A37: P300 | B37: Twitter | C37: 2024-08-31 | D37: Carousel | E37: Check out our latest carousel on twitter! | F37: 4494 | G37: 717 | H37: 45 | I37: 62916 | J37: =F37+G37+H37/I37 -> 5211.0007 | K37: =F37+G37+H37 -> 5256 | L37: 62688 | M37: 191 | N37: #PepsiCoRefresh | O37: #ThirstyForMore | P37: #BetterWithPepsi | S37: SummerSplash | T37: =IF(AND(C37>='Campaign Metadata'!B$2,Posts!C37<='Campaign Metadata'!C$2),"During","Before/After") -> Before/After | U37: =IF(AND(C37>='Campaign Metadata'!B$3,Posts!C37<='Campaign Metadata'!C$3),"During","Before/After") -> Before/After | V37: =IF(AND(C37>='Campaign Metadata'!B$4,Posts!C37<='Campaign Metadata'!C$4),"During","Before/After") -> Before/After | W37: =IF(AND(C37>='Campaign Metadata'!B$5,Posts!C37<='Campaign Metadata'!C$5),"During","Before/After") -> Before/After
A38: P239 | B38: YouTube | C38: 2025-02-24 | D38: Text | E38: Check out our latest text on youtube! | F38: 4188 | G38: 942 | H38: 118 | I38: 20940 | J38: =F38+G38+H38/I38 -> 5130.0056 | K38: =F38+G38+H38 -> 5248 | L38: 20471 | M38: 102 | N38: #LiveForNow | T38: =IF(AND(C38>='Campaign Metadata'!B$2,Posts!C38<='Campaign Metadata'!C$2),"During","Before/After") -> Before/After | U38: =IF(AND(C38>='Campaign Metadata'!B$3,Posts!C38<='Campaign Metadata'!C$3),"During","Before/After") -> Before/After | V38: =IF(AND(C38>='Campaign Metadata'!B$4,Posts!C38<='Campaign Metadata'!C$4),"During","Before/After") -> Before/After | W38: =IF(AND(C38>='Campaign Metadata'!B$5,Posts!C38<='Campaign Metadata'!C$5),"During","Before/After") -> Before/After
A39: P277 | B39: Facebook | C39: 2025-04-06 | D39: Image | E39: Check out our latest image on facebook! | F39: 4236 | G39: 711 | H39: 298 | I39: 21180 | J39: =F39+G39+H39/I39 -> 4947.0141 | K39: =F39+G39+H39 -> 5245 | L39: 20516 | M39: 238 | N39: #LiveForNow | S39: SummerSplash | T39: =IF(AND(C39>='Campaign Metadata'!B$2,Posts!C39<='Campaign Metadata'!C$2),"During","Before/After") -> Before/After | U39: =IF(AND(C39>='Campaign Metadata'!B$3,Posts!C39<='Campaign Metadata'!C$3),"During","Before/After") -> Before/After | V39: =IF(AND(C39>='Campaign Metadata'!B$4,Posts!C39<='Campaign Metadata'!C$4),"During","Before/After") -> Before/After | W39: =IF(AND(C39>='Campaign Metadata'!B$5,Posts!C39<='Campaign Metadata'!C$5),"During","Before/After") -> Before/After
A40: P182 | B40: Facebook | C40: 2024-07-31 | D40: Image | E40: Check out our latest image on facebook! | F40: 4689 | G40: 134 | H40: 403 | I40: 51579 | J40: =F40+G40+H40/I40 -> 4823.0078 | K40: =F40+G40+H40 -> 5226 | L40: 50924 | M40: 173 | N40: #PepsiCoRefresh | S40: DailyWellness | T40: =IF(AND(C40>='Campaign Metadata'!B$2,Posts!C40<='Campaign Metadata'!C$2),"During","Before/After") -> Before/After | U40: =IF(AND(C40>='Campaign Metadata'!B$3,Posts!C40<='Campaign Metadata'!C$3),"During","Before/After") -> Before/After | V40: =IF(AND(C40>='Campaign Metadata'!B$4,Posts!C40<='Campaign Metadata'!C$4),"During","Before/After") -> Before/After | W40: =IF(AND(C40>='Campaign Metadata'!B$5,Posts!C40<='Campaign Metadata'!C$5),"During","Before/After") -> Before/After
...

Sheet Campaign Metadata
A1: Campaign_Name | B1: Start_Date | C1: End_Date | D1: Objective | E1: Total_Budget | F1: Total Engaagement During Campaign | G1: Target_Platforms | H1: Primary_Hashtags
A2: SummerSplash | B2: 2024-06-15 | C2: 2024-07-15 | D2: Brand Awareness | E2: 150000 | F2: =SUMIF(Posts!T2:T301,"During",Posts!K2:K301) -> 103773 | G2: Instagram,Facebook | H2: #ThirstyForMore,#PepsiCoRefresh
A3: DailyWellness | B3: 2025-03-01 | C3: 2025-03-31 | D3: Traffic | E3: 180000 | F3: =SUMIF(Posts!W2:W301,"During",Posts!K2:K301) -> 33044 | G3: Instagram,Twitter | H3: #BetterWithPepsi,#LiveForNow
A4: FestiveRadiance | B4: 2024-10-01 | C4: 2024-10-31 | D4: Engagement | E4: 200000 | F4: =SUMIF(Posts!U2:U301,"During",Posts!K2:K301) -> 106020 | G4: Instagram,YouTube | H4: #AnytimeIsPepsiTime,
A5: NewYearRefresh | B5: 2024-12-25 | C5: 2025-01-10 | D5: Product Launch | E5: 250000 | F5: =SUMIF(Posts!V2:V301,"During",Posts!K2:K301) -> 137691 | G5: Facebook,Twitter | H5: #SmoothLikeNitroPepsi

Sheet Engagement Summary
B1: New_Followers | C1: Unfollows | D1: Total_Followers | E1: Engagement_Rate | F1: Ad_Spend | G1: Net follwers -/+ | H1: Folower Growth | I1: Campaign Name | J1: Week_Start_Date | K1: Follower Growth | L1: Platform | M1: Campign Wise Follower Growth | N1: Net Added Follower | O1: Net Added Follower%
B2: 1135 | C2: 88 | D2: 344084 | E2: 8.06 | F2: 5904 | G2: =B2-C2 -> 1047 | H2: =G2/D2*100 -> 0.30428616 | J2: 2024-06-03 | K2: 0.30428616 | L2: Instagram | M2: Summer Splash | N2: =SUMIFS(G2:G201,$I$2:$I$201,M$2) -> 13523 | O2: =N2/$D$202*100 -> 0.025570084 | Q2: Sum of Follower Growth | R2: Column Labels
B3: 1312 | C3: 310 | D3: 42654 | E3: 4.98 | F3: 9566 | G3: =B3-C3 -> 1002 | H3: =G3/D3*100 -> 2.3491349 | J3: 2024-06-03 | K3: 2.3491349 | L3: Facebook | M3: Daily Wellness | N3: =SUMIFS(G3:G202,$I$2:$I$201,M$2) -> 12789 | O3: =N3/$D$202*100 -> 0.024182193 | Q3: Row Labels | R3: Facebook | S3: Instagram | T3: Twitter | U3: YouTube | V3: (blank) | W3: Grand Total
B4: 584 | C4: 169 | D4: 146834 | E4: 8.31 | F4: 26752 | G4: =B4-C4 -> 415 | H4: =G4/D4*100 -> 0.28263209 | J4: 2024-06-03 | K4: 0.28263209 | L4: Twitter | M4: Festive Radiance | N4: =SUMIFS(G4:G203,$I$2:$I$201,M$2) -> 12368 | O4: =N4/$D$202*100 -> 0.023386142 | Q4: 2024-06-03 | R4: 2.3491349 | S4: 0.30428616 | T4: 0.28263209 | U4: 0.27557542 | W4: 3.2116286
B5: 1535 | C5: 445 | D5: 395536 | E5: 4.11 | F5: 30671 | G5: =B5-C5 -> 1090 | H5: =G5/D5*100 -> 0.27557542 | J5: 2024-06-03 | K5: 0.27557542 | L5: YouTube | M5: NewYear Refresh | N5: =SUMIFS(G5:G204,$I$2:$I$201,M$2) -> 12389 | O5: =N5/$D$202*100 -> 0.02342585 | Q5: 2024-06-10 | R5: 0.40530082 | S5: 1.0517322 | T5: 0.073128443 | U5: 0.24016739 | W5: 1.7703289
B6: 656 | C6: 139 | D6: 49157 | E6: 9.05 | F6: 9920 | G6: =B6-C6 -> 517 | H6: =G6/D6*100 -> 1.0517322 | J6: 2024-06-10 | K6: 1.0517322 | L6: Instagram | Q6: 2024-06-17 | R6: 0.81535847 | S6: 0.19542791 | T6: 1.0551445 | U6: 0.0880238 | W6: 2.1539547
B7: 1697 | C7: 414 | D7: 316555 | E7: 2.37 | F7: 7924 | G7: =B7-C7 -> 1283 | H7: =G7/D7*100 -> 0.40530082 | J7: 2024-06-10 | K7: 0.40530082 | L7: Facebook | Q7: 2024-06-24 | R7: 6.3510173 | S7: 1.7636833 | T7: 0.27980605 | U7: -0.028860774 | W7: 8.3656458
B8: 436 | C8: 250 | D8: 254347 | E8: 4.01 | F8: 8912 | G8: =B8-C8 -> 186 | H8: =G8/D8*100 -> 0.073128443 | J8: 2024-06-10 | K8: 0.073128443 | L8: Twitter | Q8: 2024-07-01 | R8: 0.029088265 | S8: -0.052211602 | T8: 0.43037694 | U8: 0.080050669 | W8: 0.48730427
B9: 1197 | C9: 203 | D9: 413878 | E9: 3.16 | F9: 21205 | G9: =B9-C9 -> 994 | H9: =G9/D9*100 -> 0.24016739 | J9: 2024-06-10 | K9: 0.24016739 | L9: YouTube | Q9: 2024-07-08 | R9: 0.12276812 | S9: 2.8717174 | T9: 0.14032477 | U9: 0.21994574 | W9: 3.354756
B10: 1048 | C10: 155 | D10: 456946 | E10: 2.46 | F10: 11329 | G10: =B10-C10 -> 893 | H10: =G10/D10*100 -> 0.19542791 | I10: Summer Splash | J10: 2024-06-17 | K10: 0.19542791 | L10: Instagram | Q10: 2024-07-15 | R10: -0.049009939 | S10: 1.1967386 | T10: 0.18982133 | U10: 0.10211701 | W10: 1.439667
B11: 1753 | C11: 371 | D11: 169496 | E11: 8.11 | F11: 46670 | G11: =B11-C11 -> 1382 | H11: =G11/D11*100 -> 0.81535847 | I11: Summer Splash | J11: 2024-06-17 | K11: 0.81535847 | L11: Facebook | Q11: 2024-07-22 | R11: 0.32572738 | S11: 0.033557614 | T11: 0.66371458 | U11: 0.10340418 | W11: 1.1264038
B12: 1335 | C12: 40 | D12: 122732 | E12: 8.19 | F12: 22482 | G12: =B12-C12 -> 1295 | H12: =G12/D12*100 -> 1.0551445 | I12: Summer Splash | J12: 2024-06-17 | K12: 1.0551445 | L12: Twitter | Q12: 2024-07-29 | R12: -0.073097735 | S12: 2.2861731 | T12: 0.51986619 | U12: 0.76001216 | W12: 3.4929537
B13: 403 | C13: 66 | D13: 382851 | E13: 3.49 | F13: 24313 | G13: =B13-C13 -> 337 | H13: =G13/D13*100 -> 0.0880238 | I13: Summer Splash | J13: 2024-06-17 | K13: 0.0880238 | L13: YouTube | Q13: 2024-08-05 | R13: -0.15755714 | S13: 0.080371169 | T13: 0.072889861 | U13: 0.09948542 | W13: 0.095189305
B14: 911 | C14: 282 | D14: 35664 | E14: 6.92 | F14: 18050 | G14: =B14-C14 -> 629 | H14: =G14/D14*100 -> 1.7636833 | I14: Summer Splash | J14: 2024-06-24 | K14: 1.7636833 | L14: Instagram | Q14: 2024-08-12 | R14: 0.43366319 | S14: 0.27085701 | T14: 0.0085080355 | U14: 1.0113483 | W14: 1.7243765
B15: 1779 | C15: 109 | D15: 26295 | E15: 9.12 | F15: 30635 | G15: =B15-C15 -> 1670 | H15: =G15/D15*100 -> 6.3510173 | I15: Summer Splash | J15: 2024-06-24 | K15: 6.3510173 | L15: Facebook | Q15: 2024-08-19 | R15: 0.5752376 | S15: 0.023352712 | T15: 0.88256341 | U15: 0.2172844 | W15: 1.6984381
B16: 1238 | C16: 403 | D16: 298421 | E16: 3.5 | F16: 31280 | G16: =B16-C16 -> 835 | H16: =G16/D16*100 -> 0.27980605 | I16: Summer Splash | J16: 2024-06-24 | K16: 0.27980605 | L16: Twitter | Q16: 2024-08-26 | R16: 0.0097527545 | S16: 0.35456226 | T16: 0.65914381 | U16: 0.011713325 | W16: 1.0351722
B17: 308 | C17: 431 | D17: 426184 | E17: 2.62 | F17: 1783 | G17: =B17-C17 -> -123 | H17: =G17/D17*100 -> -0.028860774 | I17: Summer Splash | J17: 2024-06-24 | K17: -0.028860774 | L17: YouTube | Q17: 2024-09-02 | R17: 0.21026918 | S17: 1.2306083 | T17: 0.061798299 | U17: 0.089764429 | W17: 1.5924402
B18: 226 | C18: 445 | D18: 419447 | E18: 9.36 | F18: 9566 | G18: =B18-C18 -> -219 | H18: =G18/D18*100 -> -0.052211602 | I18: Summer Splash | J18: 2024-07-01 | K18: -0.052211602 | L18: Instagram | Q18: 2024-09-09 | R18: 0.464354 | S18: 0.41581361 | T18: 0.059901347 | U18: 1.7032346 | W18: 2.6433036
B19: 505 | C19: 441 | D19: 220020 | E19: 4.48 | F19: 42307 | G19: =B19-C19 -> 64 | H19: =G19/D19*100 -> 0.029088265 | I19: Summer Splash | J19: 2024-07-01 | K19: 0.029088265 | L19: Facebook | Q19: 2024-09-16 | R19: 0.020668042 | S19: 0.74222826 | T19: 0.28673013 | U19: -0.026681341 | W19: 1.0229451
B20: 1420 | C20: 63 | D20: 315305 | E20: 6.19 | F20: 5914 | G20: =B20-C20 -> 1357 | H20: =G20/D20*100 -> 0.43037694 | I20: Summer Splash | J20: 2024-07-01 | K20: 0.43037694 | L20: Twitter | Q20: 2024-09-23 | R20: -0.0079248226 | S20: 0.15758651 | T20: 0.62566104 | U20: 1.5923516 | W20: 2.3676744
B21: 144 | C21: 53 | D21: 113678 | E21: 8.72 | F21: 30060 | G21: =B21-C21 -> 91 | H21: =G21/D21*100 -> 0.080050669 | I21: Summer Splash | J21: 2024-07-01 | K21: 0.080050669 | L21: YouTube | Q21: 2024-09-30 | R21: -0.039477486 | S21: 0.27682577 | T21: 0.92287308 | U21: 1.8079695 | W21: 2.9681908
... B29: 224 | C29: 64 | D29: 156683 | E29: 4.56 | F29: 28474 | G29: =B29-C29 -> 160 | H29: =G29/D29*100 -> 0.10211701 | I29: Summer Splash | J29: 2024-07-15 | K29: 0.10211701 | L29: YouTube | Q29: 2024-11-25 | R29: 0.39565022 | S29: 0.59936417 | T29: 0.1107908 | U29: 1.4152075 | W29: 2.5210127
B30: 508 | C30: 349 | D30: 473812 | E30: 7.88 | F30: 17328 | G30: =B30-C30 -> 159 | H30: =G30/D30*100 -> 0.033557614 | J30: 2024-07-22 | K30: 0.033557614 | L30: Instagram | Q30: 2024-12-02 | R30: 0.36277109 | S30: 0.38511033 | T30: 0.37850431 | U30: 0.13151116 | W30: 1.2578969
B31: 1391 | C31: 430 | D31: 295032 | E31: 7.86 | F31: 26067 | G31: =B31-C31 -> 961 | H31: =G31/D31*100 -> 0.32572738 | J31: 2024-07-22 | K31: 0.32572738 | L31: Facebook | Q31: 2024-12-09 | R31: 3.8307014 | S31: 0.50721616 | T31: 8.3806474 | U31: 0.12679965 | W31: 12.845365
B32: 1701 | C32: 385 | D32: 198278 | E32: 5.34 | F32: 32763 | G32: =B32-C32 -> 1316 | H32: =G32/D32*100 -> 0.66371458 | J32: 2024-07-22 | K32: 0.66371458 | L32: Twitter | Q32: 2024-12-16 | R32: 0.33115688 | S32: 0.30759119 | T32: 0.41536388 | U32: 0.17917738 | W32: 1.2332893
B33: 804 | C33: 487 | D33: 306564 | E33: 5.52 | F33: 26452 | G33: =B33-C33 -> 317 | H33: =G33/D33*100 -> 0.10340418 | J33: 2024-07-22 | K33: 0.10340418 | L33: YouTube | Q33: 2024-12-23 | R33: 0.78202835 | S33: 0.24359408 | T33: 1.1230415 | U33: 6.3113159 | W33: 8.4599798
B34: 653 | C34: 112 | D34: 23664 | E34: 4.05 | F34: 15353 | G34: =B34-C34 -> 541 | H34: =G34/D34*100 -> 2.2861731 | J34: 2024-07-29 | K34: 2.2861731 | L34: Instagram | Q34: 2024-12-30 | R34: 0.46806929 | S34: 1.2535155 | T34: 0.5563419 | U34: 1.0669005 | W34: 3.3448272
B35: 160 | C35: 478 | D35: 435034 | E35: 7.73 | F35: 4839 | G35: =B35-C35 -> -318 | H35: =G35/D35*100 -> -0.073097735 | J35: 2024-07-29 | K35: -0.073097735 | L35: Facebook | Q35: 2025-01-06 | R35: 0.64766839 | S35: 0.19361811 | T35: 0.32008104 | U35: 0.88669951 | W35: 2.0480671
B36: 1756 | C36: 261 | D36: 287574 | E36: 4.36 | F36: 39272 | G36: =B36-C36 -> 1495 | H36: =G36/D36*100 -> 0.51986619 | J36: 2024-07-29 | K36: 0.51986619 | L36: Twitter | Q36: 2025-01-13 | R36: 0.13262186 | S36: 0.49282654 | T36: -0.029514487 | U36: 6.2409088 | W36: 6.8368427
B37: 576 | C37: 101 | D37: 62499 | E37: 3.48 | F37: 16804 | G37: =B37-C37 -> 475 | H37: =G37/D37*100 -> 0.76001216 | J37: 2024-07-29 | K37: 0.76001216 | L37: YouTube | Q37: 2025-01-20 | R37: 0.089052952 | S37: 0.40971536 | T37: 0.71621491 | U37: 0.21486931 | W37: 1.4298525
B38: 645 | C38: 293 | D38: 437968 | E38: 7.83 | F38: 49303 | G38: =B38-C38 -> 352 | H38: =G38/D38*100 -> 0.080371169 | J38: 2024-08-05 | K38: 0.080371169 | L38: Instagram | Q38: 2025-01-27 | R38: 0.27948348 | S38: -0.046464109 | T38: 0.54309534 | U38: 0.26534162 | W38: 1.0414563
B39: 214 | C39: 411 | D39: 125034 | E39: 6.11 | F39: 26455 | G39: =B39-C39 -> -197 | H39: =G39/D39*100 -> -0.15755714 | J39: 2024-08-05 | K39: -0.15755714 | L39: Facebook | Q39: 2025-02-03 | R39: 0.55005258 | S39: 0.30720568 | T39: 0.32046589 | U39: -0.074972485 | W39: 1.1027517
B40: 826 | C40: 498 | D40: 449994 | E40: 9.43 | F40: 12384 | G40: =B40-C40 -> 328 | H40: =G40/D40*100 -> 0.072889861 | J40: 2024-08-05 | K40: 0.072889861 | L40: Twitter | Q40: 2025-02-10 | R40: 0.29427519 | S40: 0.77568587 | T40: 0.94958209 | U40: 0.29756017 | W40: 2.3171033
B41: 460 | C41: 141 | D41: 320650 | E41: 4.04 | F41: 49372 | G41: =B41-C41 -> 319 | H41: =G41/D41*100 -> 0.09948542 | J41: 2024-08-05 | K41: 0.09948542 | L41: YouTube | Q41: 2025-02-17 | R41: 1.5147618 | S41: 0.21291007 | T41: -0.025410692 | U41: 1.1086998 | W41: 2.8109609
... B53: 422 | C53: 394 | D53: 239044 | E53: 7.83 | F53: 32929 | G53: =B53-C53 -> 28 | H53: =G53/D53*100 -> 0.011713325 | J53: 2024-08-26 | K53: 0.011713325 | L53: YouTube | Q53: 2025-05-12 | R53: 0.11156187 | S53: 0.35361872 | T53: 0.058952702 | U53: -0.40819787 | W53: 0.11593541
B54: 1429 | C54: 182 | D54: 101332 | E54: 7.16 | F54: 37829 | G54: =B54-C54 -> 1247 | H54: =G54/D54*100 -> 1.2306083 | J54: 2024-09-02 | K54: 1.2306083 | L54: Instagram | Q54: (blank)
B55: 1520 | C55: 475 | D55: 496982 | E55: 6.41 | F55: 24384 | G55: =B55-C55 -> 1045 | H55: =G55/D55*100 -> 0.21026918 | J55: 2024-09-02 | K55: 0.21026918 | L55: Facebook | Q55: Grand Total | R55: 27.324953 | S55: 28.812661 | T55: 46.400128 | U55: 45.105333 | W55: 147.64308
B56: 557 | C56: 360 | D56: 318779 | E56: 8.02 | F56: 25797 | G56: =B56-C56 -> 197 | H56: =G56/D56*100 -> 0.061798299 | J56: 2024-09-02 | K56: 0.061798299 | L56: Twitter
B57: 728 | C57: 395 | D57: 370971 | E57: 3.86 | F57: 12646 | G57: =B57-C57 -> 333 | H57: =G57/D57*100 -> 0.089764429 | J57: 2024-09-02 | K57: 0.089764429 | L57: YouTube
B58: 1592 | C58: 20 | D58: 378054 | E58: 9.09 | F58: 26663 | G58: =B58-C58 -> 1572 | H58: =G58/D58*100 -> 0.41581361 | J58: 2024-09-09 | K58: 0.41581361 | L58: Instagram
...

Sheet Engagement Analysis 1
A35: Hashtags | B35: Count | C35: Rank | E35: Row Labels | F35: Sum of Total Engagement | H35: Hastags | I35: Count
A36: #PepsiCoRefresh | B36: 107 | C36: =RANK(B36,$B$36:$B$53) -> 1 | E36: Facebook | F36: 5973 | H36: #PepsiCoRefresh | I36: =COUNTIF(Posts!N2:P301,"#PepsiCoRefresh") -> 107
A37: #LiveForNow | B37: 103 | C37: =RANK(B37,$B$36:$B$53) -> 2 | E37: Image | F37: 5973 | H37: #ThirstyForMore | I37: =COUNTIF(Posts!N2:P301,"#ThirstyForMore") -> 102
A38: #ThirstyForMore | B38: 102 | C38: =RANK(B38,$B$36:$B$53) -> 3 | E38: Instagram | F38: 17869 | H38: #LiveForNow | I38: =COUNTIF(Posts!N2:P301,"#LiveForNow") -> 103 | AF38: Row Labels | AG38: Sum of Count
A39: #AnytimeIsPepsiTime | B39: 15 | C39: =RANK(B39,$B$36:$B$53) -> 4 | E39: Image | F39: 11969 | H39: #SmoothLikeNitroPepsi | I39: =COUNTIF(Posts!N2:P301,"#SmoothLikeNitroPepsi") -> 5 | AF39: #AnytimeIsPepsiTime | AG39: 15
A40: #BetterWithPepsi | B40: 15 | C40: =RANK(B40,$B$36:$B$53) -> 4 | E40: Story | F40: 5900 | H40: #AnytimeIsPepsiTime | I40: =COUNTIF(Posts!N2:P301,"#AnytimeIsPepsiTime") -> 15 | AF40: #BetterWithPepsi | AG40: 15
A41: #SmoothLikeNitroPepsi | B41: 5 | C41: =RANK(B41,$B$36:$B$53) -> 6 | E41: Twitter | F41: 12191 | H41: #BetterWithPepsi | I41: =COUNTIF(Posts!N2:P301,"#AnytimeIsPepsiTime") -> 15 | AF41: #LiveForNow | AG41: 103
E42: Text | F42: 5913 | AF42: #PepsiCoRefresh | AG42: 107
A43: Platform | B43: Content Type | C43: Total Engagement | E43: Video | F43: 6278 | H43: Row Labels | I43: Sum of Average Engagement Rate | AF43: #SmoothLikeNitroPepsi | AG43: 5
A44: Twitter | B44: Video | C44: 6278 | E44: YouTube | F44: 24099 | H44: #AnytimeIsPepsiTime | I44: 5690.0047 | AF44: #ThirstyForMore | AG44: 102
A45: YouTube | B45: Story | C45: 6130 | E45: Image | F45: 5879 | H45: #BetterWithPepsi | I45: 5440.0072 | AF45: Grand Total | AG45: 347
A46: YouTube | B46: Text | C46: 6061 | E46: Story | F46: 6130 | H46: #LiveForNow | I46: 5905.004
A47: Instagram | B47: Image | C47: 6030 | E47: Text | F47: 6061 | H47: #PepsiCoRefresh | I47: 11465.028
A48: YouTube | B48: Video | C48: 6029 | E48: Video | F48: 6029 | H48: #SmoothLikeNitroPepsi | I48: 5547.0071
A49: Facebook | B49: Image | C49: 5973 | E49: Grand Total | F49: 60132 | H49: #ThirstyForMore | I49: 11475.007
A50: Instagram | B50: Image | C50: 5939 | H50: Grand Total | I50: 45522.058
A51: Twitter | B51: Text | C51: 5913
A52: Instagram | B52: Story | C52: 5900
A53: YouTube | B53: Image | C53: 5879

Sheet SocialMedia Platform Analysis 2
W1: Row Labels | X1: Sum of Folower Growth
W2: Facebook | X2: 27.324953
W3: Instagram | X3: 28.812661
W4: Twitter | X4: 46.400128
W5: YouTube | X5: 45.105333
W6: Grand Total | X6: 147.64308
W9: Row Labels | X9: Sum of Ad_Spend
W10: Facebook | X10: 1379539
W11: Instagram | X11: 1164373
W12: Twitter | X12: 1060357
W13: YouTube | X13: 1228647
W14: Grand Total | X14: 4832916
W16: Platform | X16: Total Engagement | Y16: Ad Spend
W17: {=_xlfn.UNIQUE(Posts!B2:B301)} -> Twitter | X17: =SUMIF(Posts!B2:B301,"Twitter",Posts!K2:K301) -> 256005 | Y17: =SUMIF('Engagement Summary'!L2:L201,"Twitter",'Engagement Summary'!F2:F201) -> 1060357
W18: YouTube | X18: =SUMIF(Posts!B2:B301,"YouTube",Posts!K2:K301) -> 212941 | Y18: =SUMIF('Engagement Summary'!L2:L201,"YouTube",'Engagement Summary'!F2:F201) -> 1228647
W19: Instagram | X19: =SUMIF(Posts!B2:B301,"Instagram",Posts!K2:K301) -> 263579 | Y19: =SUMIF('Engagement Summary'!L2:L201,"Instagram",'Engagement Summary'!F2:F201) -> 1164373
W20: Facebook | X20: =SUMIF(Posts!B2:B301,"Facebook",Posts!K2:K301) -> 305242 | Y20: =SUMIF('Engagement Summary'!L2:L201,"Facebook",'Engagement Summary'!F2:F201) -> 1379539

Sheet HasTags & Content Strategy 3
W1: Row Labels | X1: Sum of Average Engagement Rate
W2: #AnytimeIsPepsiTime | X2: 5690.0047
W3: #BetterWithPepsi | X3: 5440.0072
W4: #LiveForNow | X4: 5905.004
W5: #PepsiCoRefresh | X5: 11465.028
W6: #SmoothLikeNitroPepsi | X6: 5547.0071
W7: #ThirstyForMore | X7: 11475.007
W8: Grand Total | X8: 45522.058
W10: Row Labels | X10: Sum of Reach
W11: Carousel | X11: 2084819
W12: Facebook | X12: 558118
W13: Instagram | X13: 526691
W14: Twitter | X14: 609023
W15: YouTube | X15: 390987
W16: Image | X16: 2224104
W17: Facebook | X17: 975067
W18: Instagram | X18: 388193
W19: Twitter | X19: 490353
W20: YouTube | X20: 370491
W21: Reel | X21: 1630594
W22: Facebook | X22: 482519
... W41: Grand Total | X41: 10231623
W43: Row Labels | X43: Sum of Count of Hashtags
W44: #AnytimeIsPepsiTime | X44: 15
W45: #BetterWithPepsi | X45: 7
W46: #LiveForNow | X46: 103
W47: #PepsiCoRefresh | X47: 214
W48: #SmoothLikeNitroPepsi | X48: 5
W49: #ThirstyForMore | X49: 204
W50: Grand Total | X50: 548

Sheet Campaign Efectiveness 4
AD1: Campaign Name | AE1: Total Impresions
AD2: {=_xlfn.UNIQUE(Posts!S2:S301)} -> SummerSplash | AE2: =SUMIF(Posts!$S$2:$S$301,'Campaign Efectiveness 4'!AD2,Posts!$I$2:$I$301) -> 1846272
AD3: DailyWellness | AE3: =SUMIF(Posts!$S$2:$S$301,'Campaign Efectiveness 4'!AD3,Posts!$I$2:$I$301) -> 2464864
AD4: NewYearRefresh | AE4: =SUMIF(Posts!$S$2:$S$301,'Campaign Efectiveness 4'!AD4,Posts!$I$2:$I$301) -> 2266053
AD5: FestiveRadiance | AE5: =SUMIF(Posts!$S$2:$S$301,'Campaign Efectiveness 4'!AD5,Posts!$I$2:$I$301) -> 1986356
AD6: 0
AD8: Campaign Name | AE8: Total Likes
AD9: SummerSplash | AE9: =SUMIF(Posts!$S:$S,'Campaign Efectiveness 4'!AD9,Posts!F2:F301) -> 136302
AD10: DailyWellness | AE10: =SUMIF(Posts!$S:$S,'Campaign Efectiveness 4'!AD10,Posts!F3:F302) -> 187249
AD11: NewYearRefresh | AE11: =SUMIF(Posts!$S:$S,'Campaign Efectiveness 4'!AD11,Posts!F4:F303) -> 184943
AD12: FestiveRadiance | AE12: =SUMIF(Posts!$S:$S,'Campaign Efectiveness 4'!AD12,Posts!F5:F304) -> 155500
AD14: Campaign Name | AE14: Total Clicks
AD15: SummerSplash | AE15: =SUMIF(Posts!$S:$S,'Campaign Efectiveness 4'!AD15,Posts!M:M) -> 6434
AD16: DailyWellness | AE16: =SUMIF(Posts!$S:$S,'Campaign Efectiveness 4'!AD16,Posts!M:M) -> 10689
AD17: NewYearRefresh | AE17: =SUMIF(Posts!$S:$S,'Campaign Efectiveness 4'!AD17,Posts!M:M) -> 10032
AD18: FestiveRadiance | AE18: =SUMIF(Posts!$S:$S,'Campaign Efectiveness 4'!AD18,Posts!M:M) -> 9872
AD20: Campaign Name | AE20: Average Impresion
AD21: SummerSplash | AE21: =AVERAGEIF(Posts!$S:$S,'Campaign Efectiveness 4'!AD21,Posts!I2:I301) -> 36356.292
AD22: DailyWellness | AE22: =AVERAGEIF(Posts!$S:$S,'Campaign Efectiveness 4'!AD22,Posts!I3:I302) -> 36277.07
AD23: NewYearRefresh | AE23: =AVERAGEIF(Posts!$S:$S,'Campaign Efectiveness 4'!AD23,Posts!I4:I303) -> 35070.803
AD24: FestiveRadiance | AE24: =AVERAGEIF(Posts!$S:$S,'Campaign Efectiveness 4'!AD24,Posts!I5:I304) -> 36418.071
AD26: Campaign Name | AE26: Average Likes
AD27: SummerSplash | AE27: =AVERAGEIF(Posts!$S$2:$S$301,'Campaign Efectiveness 4'!AD27,Posts!$F:$F) -> 2879.5745
AD28: DailyWellness | AE28: =AVERAGEIF(Posts!$S$2:$S$301,'Campaign Efectiveness 4'!AD28,Posts!$F:$F) -> 2598.0282
AD29: NewYearRefresh | AE29: =AVERAGEIF(Posts!$S$2:$S$301,'Campaign Efectiveness 4'!AD29,Posts!$F:$F) -> 2829.5224
AD30: FestiveRadiance | AE30: =AVERAGEIF(Posts!$S$2:$S$301,'Campaign Efectiveness 4'!AD30,Posts!$F:$F) -> 2806.4828
AD32: Campaign Name | AE32: Average Clicks
AD33: SummerSplash | AE33: =AVERAGEIF(Posts!$S:$S,'Campaign Efectiveness 4'!AD33,Posts!$M:$M) -> 134.04167
AD34: DailyWellness | AE34: =AVERAGEIF(Posts!$S:$S,'Campaign Efectiveness 4'!AD34,Posts!$M:$M) -> 150.5493
AD35: NewYearRefresh | AE35: =AVERAGEIF(Posts!$S:$S,'Campaign Efectiveness 4'!AD35,Posts!$M:$M) -> 149.73134
AD36: FestiveRadiance | AE36: =AVERAGEIF(Posts!$S:$S,'Campaign Efectiveness 4'!AD36,Posts!$M:$M) -> 170.2069

Sheet Follower Retention & Audience 5

Sheet Video Explanation Link
A1: Video Explanation Drive Link
A2: https://drive.google.com/file/d/1uEgTZugu5U6_o9mg2Bqp61beN8XTSkER/view?usp=drive_link
